2025-02-04 18:22:59,093 - discord.client - INFO - logging in using static token
2025-02-04 18:22:59,783 - bot.connection - INFO - Starting web server on 0.0.0.0:8080
2025-02-04 18:22:59,785 - bot.connection - INFO - Web server running at http://0.0.0.0:8080
2025-02-04 18:22:59,913 - bot.commands - INFO - Cleared commands from guild 947925127654412370
2025-02-04 18:23:00,263 - bot.commands - INFO - Synced commands globally
2025-02-04 18:23:01,873 - discord.gateway - INFO - Shard ID None has connected to Gateway (Session ID: 061bef351bc61d1ac7722987b1cda5b1).
2025-02-04 18:23:05,736 - bot.connection - INFO - Web server shutdown complete
2025-02-05 13:46:34,008 - discord.client - INFO - logging in using static token
2025-02-05 13:46:36,379 - bot.connection - INFO - Starting web server on 0.0.0.0:8080
2025-02-05 13:46:36,391 - bot.connection - INFO - Web server running at http://0.0.0.0:8080
2025-02-05 13:46:36,614 - bot.commands - INFO - Cleared commands from guild 947925127654412370
2025-02-05 13:46:36,926 - bot.commands - INFO - Synced commands globally
2025-02-05 13:46:37,515 - discord.gateway - INFO - Shard ID None has connected to Gateway (Session ID: 4e9193349395223d07467a917b7d31da).
2025-02-05 13:53:26,166 - bot.connection - INFO - Web server shutdown complete
2025-02-05 13:53:29,132 - discord.client - INFO - logging in using static token
2025-02-05 13:53:29,755 - bot.connection - INFO - Starting web server on 0.0.0.0:8080
2025-02-05 13:53:29,756 - bot.connection - INFO - Web server running at http://0.0.0.0:8080
2025-02-05 13:53:29,913 - bot.commands - INFO - Cleared commands from guild 947925127654412370
2025-02-05 13:53:30,194 - bot.commands - INFO - Synced commands globally
2025-02-05 13:53:30,630 - discord.gateway - INFO - Shard ID None has connected to Gateway (Session ID: 50e513f591ffefaf22d63227251c9460).
2025-02-05 14:00:17,146 - bot.connection - INFO - Web server shutdown complete
2025-02-05 14:00:19,834 - discord.client - INFO - logging in using static token
2025-02-05 14:00:20,448 - bot.connection - INFO - Starting web server on 0.0.0.0:8080
2025-02-05 14:00:20,449 - bot.connection - INFO - Web server running at http://0.0.0.0:8080
2025-02-05 14:00:20,589 - bot.commands - INFO - Cleared commands from guild 947925127654412370
2025-02-05 14:00:20,932 - bot.commands - INFO - Synced commands globally
2025-02-05 14:00:21,491 - discord.gateway - INFO - Shard ID None has connected to Gateway (Session ID: 7a560e2a3ad1a91028fa3bf6b4a2be4d).
2025-02-05 14:00:39,664 - discord.client - ERROR - Ignoring exception in on_message
Traceback (most recent call last):
  File "C:\Users\techd\AppData\Roaming\Python\Python313\site-packages\discord\client.py", line 449, in _run_event
    await coro(*args, **kwargs)
  File "g:\Shared\Project Maplebot\bot\main.py", line 1023, in wrapper
    return await func(*args, **kwargs)
           ^^^^^^^^^^^^^^^^^^^^^^^^^^^
  File "g:\Shared\Project Maplebot\bot\main.py", line 1169, in on_message
    word = pronoun_replacer.replace(word)
  File "g:\Shared\Project Maplebot\bot\wordbanks.py", line 441, in replace
    text = re.sub(pattern, replacement, text, flags=re.IGNORECASE)
  File "C:\Program Files\Python313\Lib\re\__init__.py", line 208, in sub
    return _compile(pattern, flags).sub(repl, string, count)
           ~~~~~~~~^^^^^^^^^^^^^^^^
  File "C:\Program Files\Python313\Lib\re\__init__.py", line 345, in _compile
    raise ValueError(
        "cannot process flags argument with a compiled pattern")
ValueError: cannot process flags argument with a compiled pattern
2025-02-05 14:01:07,565 - bot.connection - INFO - Web server shutdown complete
2025-02-05 14:05:07,522 - discord.client - INFO - logging in using static token
2025-02-05 14:05:08,136 - bot.connection - INFO - Starting web server on 0.0.0.0:8080
2025-02-05 14:05:08,137 - bot.connection - INFO - Web server running at http://0.0.0.0:8080
2025-02-05 14:05:08,300 - bot.commands - INFO - Cleared commands from guild 947925127654412370
2025-02-05 14:05:08,521 - bot.commands - INFO - Synced commands globally
2025-02-05 14:05:08,964 - discord.gateway - INFO - Shard ID None has connected to Gateway (Session ID: aea223f57df891ec0f4b53737671fd18).
2025-02-05 14:16:38,426 - bot.connection - INFO - Web server shutdown complete
2025-02-05 14:16:41,957 - discord.client - INFO - logging in using static token
2025-02-05 14:16:42,515 - bot.connection - INFO - Starting web server on 0.0.0.0:8080
2025-02-05 14:16:42,516 - bot.connection - INFO - Web server running at http://0.0.0.0:8080
2025-02-05 14:16:42,713 - bot.commands - INFO - Cleared commands from guild 947925127654412370
2025-02-05 14:16:43,038 - bot.commands - INFO - Synced commands globally
2025-02-05 14:16:43,592 - discord.gateway - INFO - Shard ID None has connected to Gateway (Session ID: f9789271a3d1802ff371a816f1aebd86).
2025-02-05 14:25:17,897 - bot.connection - INFO - Web server shutdown complete
2025-02-05 14:25:20,644 - discord.client - INFO - logging in using static token
2025-02-05 14:25:22,101 - bot.connection - INFO - Starting web server on 0.0.0.0:8080
2025-02-05 14:25:22,103 - bot.connection - INFO - Web server running at http://0.0.0.0:8080
2025-02-05 14:25:22,265 - bot.commands - INFO - Cleared commands from guild 947925127654412370
2025-02-05 14:25:22,505 - bot.commands - INFO - Synced commands globally
2025-02-05 14:25:22,983 - discord.gateway - INFO - Shard ID None has connected to Gateway (Session ID: 95dcb6d21c2e18b9e2229f95523d370a).
2025-02-05 14:31:12,733 - discord.client - ERROR - Attempting a reconnect in 0.97s
Traceback (most recent call last):
  File "C:\Users\techd\AppData\Roaming\Python\Python313\site-packages\aiohttp\connector.py", line 1351, in _create_direct_connection
    hosts = await self._resolve_host(host, port, traces=traces)
            ^^^^^^^^^^^^^^^^^^^^^^^^^^^^^^^^^^^^^^^^^^^^^^^^^^^
  File "C:\Users\techd\AppData\Roaming\Python\Python313\site-packages\aiohttp\connector.py", line 995, in _resolve_host
    return await asyncio.shield(resolved_host_task)
           ^^^^^^^^^^^^^^^^^^^^^^^^^^^^^^^^^^^^^^^^
  File "C:\Users\techd\AppData\Roaming\Python\Python313\site-packages\aiohttp\connector.py", line 1026, in _resolve_host_with_throttle
    addrs = await self._resolver.resolve(host, port, family=self._family)
            ^^^^^^^^^^^^^^^^^^^^^^^^^^^^^^^^^^^^^^^^^^^^^^^^^^^^^^^^^^^^^
  File "C:\Users\techd\AppData\Roaming\Python\Python313\site-packages\aiohttp\resolver.py", line 36, in resolve
    infos = await self._loop.getaddrinfo(
            ^^^^^^^^^^^^^^^^^^^^^^^^^^^^^
    ...<5 lines>...
    )
    ^
  File "C:\Program Files\Python313\Lib\asyncio\base_events.py", line 934, in getaddrinfo
    return await self.run_in_executor(
           ^^^^^^^^^^^^^^^^^^^^^^^^^^^
        None, getaddr_func, host, port, family, type, proto, flags)
        ^^^^^^^^^^^^^^^^^^^^^^^^^^^^^^^^^^^^^^^^^^^^^^^^^^^^^^^^^^^
  File "C:\Program Files\Python313\Lib\concurrent\futures\thread.py", line 59, in run
    result = self.fn(*self.args, **self.kwargs)
  File "C:\Program Files\Python313\Lib\socket.py", line 975, in getaddrinfo
    for res in _socket.getaddrinfo(host, port, family, type, proto, flags):
               ~~~~~~~~~~~~~~~~~~~^^^^^^^^^^^^^^^^^^^^^^^^^^^^^^^^^^^^^^^^
socket.gaierror: [Errno 11001] getaddrinfo failed

The above exception was the direct cause of the following exception:

Traceback (most recent call last):
  File "C:\Users\techd\AppData\Roaming\Python\Python313\site-packages\discord\client.py", line 664, in connect
    self.ws = await asyncio.wait_for(coro, timeout=60.0)
              ^^^^^^^^^^^^^^^^^^^^^^^^^^^^^^^^^^^^^^^^^^
  File "C:\Program Files\Python313\Lib\asyncio\tasks.py", line 507, in wait_for
    return await fut
           ^^^^^^^^^
  File "C:\Users\techd\AppData\Roaming\Python\Python313\site-packages\discord\gateway.py", line 374, in from_client
    socket = await client.http.ws_connect(str(url))
             ^^^^^^^^^^^^^^^^^^^^^^^^^^^^^^^^^^^^^^
  File "C:\Users\techd\AppData\Roaming\Python\Python313\site-packages\discord\http.py", line 550, in ws_connect
    return await self.__session.ws_connect(url, **kwargs)
           ^^^^^^^^^^^^^^^^^^^^^^^^^^^^^^^^^^^^^^^^^^^^^^
  File "C:\Users\techd\AppData\Roaming\Python\Python313\site-packages\aiohttp\client.py", line 1004, in _ws_connect
    resp = await self.request(
           ^^^^^^^^^^^^^^^^^^^
    ...<11 lines>...
    )
    ^
  File "C:\Users\techd\AppData\Roaming\Python\Python313\site-packages\aiohttp\client.py", line 703, in _request
    conn = await self._connector.connect(
           ^^^^^^^^^^^^^^^^^^^^^^^^^^^^^^
        req, traces=traces, timeout=real_timeout
        ^^^^^^^^^^^^^^^^^^^^^^^^^^^^^^^^^^^^^^^^
    )
    ^
  File "C:\Users\techd\AppData\Roaming\Python\Python313\site-packages\aiohttp\connector.py", line 548, in connect
    proto = await self._create_connection(req, traces, timeout)
            ^^^^^^^^^^^^^^^^^^^^^^^^^^^^^^^^^^^^^^^^^^^^^^^^^^^
  File "C:\Users\techd\AppData\Roaming\Python\Python313\site-packages\aiohttp\connector.py", line 1056, in _create_connection
    _, proto = await self._create_direct_connection(req, traces, timeout)
               ^^^^^^^^^^^^^^^^^^^^^^^^^^^^^^^^^^^^^^^^^^^^^^^^^^^^^^^^^^
  File "C:\Users\techd\AppData\Roaming\Python\Python313\site-packages\aiohttp\connector.py", line 1357, in _create_direct_connection
    raise ClientConnectorDNSError(req.connection_key, exc) from exc
aiohttp.client_exceptions.ClientConnectorDNSError: Cannot connect to host gateway-us-east1-d.discord.gg:443 ssl:default [getaddrinfo failed]
2025-02-05 14:31:13,828 - discord.client - ERROR - Attempting a reconnect in 2.39s
Traceback (most recent call last):
  File "C:\Users\techd\AppData\Roaming\Python\Python313\site-packages\aiohttp\connector.py", line 1351, in _create_direct_connection
    hosts = await self._resolve_host(host, port, traces=traces)
            ^^^^^^^^^^^^^^^^^^^^^^^^^^^^^^^^^^^^^^^^^^^^^^^^^^^
  File "C:\Users\techd\AppData\Roaming\Python\Python313\site-packages\aiohttp\connector.py", line 995, in _resolve_host
    return await asyncio.shield(resolved_host_task)
           ^^^^^^^^^^^^^^^^^^^^^^^^^^^^^^^^^^^^^^^^
  File "C:\Users\techd\AppData\Roaming\Python\Python313\site-packages\aiohttp\connector.py", line 1026, in _resolve_host_with_throttle
    addrs = await self._resolver.resolve(host, port, family=self._family)
            ^^^^^^^^^^^^^^^^^^^^^^^^^^^^^^^^^^^^^^^^^^^^^^^^^^^^^^^^^^^^^
  File "C:\Users\techd\AppData\Roaming\Python\Python313\site-packages\aiohttp\resolver.py", line 36, in resolve
    infos = await self._loop.getaddrinfo(
            ^^^^^^^^^^^^^^^^^^^^^^^^^^^^^
    ...<5 lines>...
    )
    ^
  File "C:\Program Files\Python313\Lib\asyncio\base_events.py", line 934, in getaddrinfo
    return await self.run_in_executor(
           ^^^^^^^^^^^^^^^^^^^^^^^^^^^
        None, getaddr_func, host, port, family, type, proto, flags)
        ^^^^^^^^^^^^^^^^^^^^^^^^^^^^^^^^^^^^^^^^^^^^^^^^^^^^^^^^^^^
  File "C:\Program Files\Python313\Lib\concurrent\futures\thread.py", line 59, in run
    result = self.fn(*self.args, **self.kwargs)
  File "C:\Program Files\Python313\Lib\socket.py", line 975, in getaddrinfo
    for res in _socket.getaddrinfo(host, port, family, type, proto, flags):
               ~~~~~~~~~~~~~~~~~~~^^^^^^^^^^^^^^^^^^^^^^^^^^^^^^^^^^^^^^^^
socket.gaierror: [Errno 11001] getaddrinfo failed

The above exception was the direct cause of the following exception:

Traceback (most recent call last):
  File "C:\Users\techd\AppData\Roaming\Python\Python313\site-packages\discord\client.py", line 664, in connect
    self.ws = await asyncio.wait_for(coro, timeout=60.0)
              ^^^^^^^^^^^^^^^^^^^^^^^^^^^^^^^^^^^^^^^^^^
  File "C:\Program Files\Python313\Lib\asyncio\tasks.py", line 507, in wait_for
    return await fut
           ^^^^^^^^^
  File "C:\Users\techd\AppData\Roaming\Python\Python313\site-packages\discord\gateway.py", line 374, in from_client
    socket = await client.http.ws_connect(str(url))
             ^^^^^^^^^^^^^^^^^^^^^^^^^^^^^^^^^^^^^^
  File "C:\Users\techd\AppData\Roaming\Python\Python313\site-packages\discord\http.py", line 550, in ws_connect
    return await self.__session.ws_connect(url, **kwargs)
           ^^^^^^^^^^^^^^^^^^^^^^^^^^^^^^^^^^^^^^^^^^^^^^
  File "C:\Users\techd\AppData\Roaming\Python\Python313\site-packages\aiohttp\client.py", line 1004, in _ws_connect
    resp = await self.request(
           ^^^^^^^^^^^^^^^^^^^
    ...<11 lines>...
    )
    ^
  File "C:\Users\techd\AppData\Roaming\Python\Python313\site-packages\aiohttp\client.py", line 703, in _request
    conn = await self._connector.connect(
           ^^^^^^^^^^^^^^^^^^^^^^^^^^^^^^
        req, traces=traces, timeout=real_timeout
        ^^^^^^^^^^^^^^^^^^^^^^^^^^^^^^^^^^^^^^^^
    )
    ^
  File "C:\Users\techd\AppData\Roaming\Python\Python313\site-packages\aiohttp\connector.py", line 548, in connect
    proto = await self._create_connection(req, traces, timeout)
            ^^^^^^^^^^^^^^^^^^^^^^^^^^^^^^^^^^^^^^^^^^^^^^^^^^^
  File "C:\Users\techd\AppData\Roaming\Python\Python313\site-packages\aiohttp\connector.py", line 1056, in _create_connection
    _, proto = await self._create_direct_connection(req, traces, timeout)
               ^^^^^^^^^^^^^^^^^^^^^^^^^^^^^^^^^^^^^^^^^^^^^^^^^^^^^^^^^^
  File "C:\Users\techd\AppData\Roaming\Python\Python313\site-packages\aiohttp\connector.py", line 1357, in _create_direct_connection
    raise ClientConnectorDNSError(req.connection_key, exc) from exc
aiohttp.client_exceptions.ClientConnectorDNSError: Cannot connect to host gateway-us-east1-d.discord.gg:443 ssl:default [getaddrinfo failed]
2025-02-05 14:31:16,236 - discord.client - ERROR - Attempting a reconnect in 5.48s
Traceback (most recent call last):
  File "C:\Users\techd\AppData\Roaming\Python\Python313\site-packages\aiohttp\connector.py", line 1351, in _create_direct_connection
    hosts = await self._resolve_host(host, port, traces=traces)
            ^^^^^^^^^^^^^^^^^^^^^^^^^^^^^^^^^^^^^^^^^^^^^^^^^^^
  File "C:\Users\techd\AppData\Roaming\Python\Python313\site-packages\aiohttp\connector.py", line 995, in _resolve_host
    return await asyncio.shield(resolved_host_task)
           ^^^^^^^^^^^^^^^^^^^^^^^^^^^^^^^^^^^^^^^^
  File "C:\Users\techd\AppData\Roaming\Python\Python313\site-packages\aiohttp\connector.py", line 1026, in _resolve_host_with_throttle
    addrs = await self._resolver.resolve(host, port, family=self._family)
            ^^^^^^^^^^^^^^^^^^^^^^^^^^^^^^^^^^^^^^^^^^^^^^^^^^^^^^^^^^^^^
  File "C:\Users\techd\AppData\Roaming\Python\Python313\site-packages\aiohttp\resolver.py", line 36, in resolve
    infos = await self._loop.getaddrinfo(
            ^^^^^^^^^^^^^^^^^^^^^^^^^^^^^
    ...<5 lines>...
    )
    ^
  File "C:\Program Files\Python313\Lib\asyncio\base_events.py", line 934, in getaddrinfo
    return await self.run_in_executor(
           ^^^^^^^^^^^^^^^^^^^^^^^^^^^
        None, getaddr_func, host, port, family, type, proto, flags)
        ^^^^^^^^^^^^^^^^^^^^^^^^^^^^^^^^^^^^^^^^^^^^^^^^^^^^^^^^^^^
  File "C:\Program Files\Python313\Lib\concurrent\futures\thread.py", line 59, in run
    result = self.fn(*self.args, **self.kwargs)
  File "C:\Program Files\Python313\Lib\socket.py", line 975, in getaddrinfo
    for res in _socket.getaddrinfo(host, port, family, type, proto, flags):
               ~~~~~~~~~~~~~~~~~~~^^^^^^^^^^^^^^^^^^^^^^^^^^^^^^^^^^^^^^^^
socket.gaierror: [Errno 11001] getaddrinfo failed

The above exception was the direct cause of the following exception:

Traceback (most recent call last):
  File "C:\Users\techd\AppData\Roaming\Python\Python313\site-packages\discord\client.py", line 664, in connect
    self.ws = await asyncio.wait_for(coro, timeout=60.0)
              ^^^^^^^^^^^^^^^^^^^^^^^^^^^^^^^^^^^^^^^^^^
  File "C:\Program Files\Python313\Lib\asyncio\tasks.py", line 507, in wait_for
    return await fut
           ^^^^^^^^^
  File "C:\Users\techd\AppData\Roaming\Python\Python313\site-packages\discord\gateway.py", line 374, in from_client
    socket = await client.http.ws_connect(str(url))
             ^^^^^^^^^^^^^^^^^^^^^^^^^^^^^^^^^^^^^^
  File "C:\Users\techd\AppData\Roaming\Python\Python313\site-packages\discord\http.py", line 550, in ws_connect
    return await self.__session.ws_connect(url, **kwargs)
           ^^^^^^^^^^^^^^^^^^^^^^^^^^^^^^^^^^^^^^^^^^^^^^
  File "C:\Users\techd\AppData\Roaming\Python\Python313\site-packages\aiohttp\client.py", line 1004, in _ws_connect
    resp = await self.request(
           ^^^^^^^^^^^^^^^^^^^
    ...<11 lines>...
    )
    ^
  File "C:\Users\techd\AppData\Roaming\Python\Python313\site-packages\aiohttp\client.py", line 703, in _request
    conn = await self._connector.connect(
           ^^^^^^^^^^^^^^^^^^^^^^^^^^^^^^
        req, traces=traces, timeout=real_timeout
        ^^^^^^^^^^^^^^^^^^^^^^^^^^^^^^^^^^^^^^^^
    )
    ^
  File "C:\Users\techd\AppData\Roaming\Python\Python313\site-packages\aiohttp\connector.py", line 548, in connect
    proto = await self._create_connection(req, traces, timeout)
            ^^^^^^^^^^^^^^^^^^^^^^^^^^^^^^^^^^^^^^^^^^^^^^^^^^^
  File "C:\Users\techd\AppData\Roaming\Python\Python313\site-packages\aiohttp\connector.py", line 1056, in _create_connection
    _, proto = await self._create_direct_connection(req, traces, timeout)
               ^^^^^^^^^^^^^^^^^^^^^^^^^^^^^^^^^^^^^^^^^^^^^^^^^^^^^^^^^^
  File "C:\Users\techd\AppData\Roaming\Python\Python313\site-packages\aiohttp\connector.py", line 1357, in _create_direct_connection
    raise ClientConnectorDNSError(req.connection_key, exc) from exc
aiohttp.client_exceptions.ClientConnectorDNSError: Cannot connect to host gateway-us-east1-d.discord.gg:443 ssl:default [getaddrinfo failed]
2025-02-05 14:31:21,726 - discord.client - ERROR - Attempting a reconnect in 8.56s
Traceback (most recent call last):
  File "C:\Users\techd\AppData\Roaming\Python\Python313\site-packages\aiohttp\connector.py", line 1351, in _create_direct_connection
    hosts = await self._resolve_host(host, port, traces=traces)
            ^^^^^^^^^^^^^^^^^^^^^^^^^^^^^^^^^^^^^^^^^^^^^^^^^^^
  File "C:\Users\techd\AppData\Roaming\Python\Python313\site-packages\aiohttp\connector.py", line 995, in _resolve_host
    return await asyncio.shield(resolved_host_task)
           ^^^^^^^^^^^^^^^^^^^^^^^^^^^^^^^^^^^^^^^^
  File "C:\Users\techd\AppData\Roaming\Python\Python313\site-packages\aiohttp\connector.py", line 1026, in _resolve_host_with_throttle
    addrs = await self._resolver.resolve(host, port, family=self._family)
            ^^^^^^^^^^^^^^^^^^^^^^^^^^^^^^^^^^^^^^^^^^^^^^^^^^^^^^^^^^^^^
  File "C:\Users\techd\AppData\Roaming\Python\Python313\site-packages\aiohttp\resolver.py", line 36, in resolve
    infos = await self._loop.getaddrinfo(
            ^^^^^^^^^^^^^^^^^^^^^^^^^^^^^
    ...<5 lines>...
    )
    ^
  File "C:\Program Files\Python313\Lib\asyncio\base_events.py", line 934, in getaddrinfo
    return await self.run_in_executor(
           ^^^^^^^^^^^^^^^^^^^^^^^^^^^
        None, getaddr_func, host, port, family, type, proto, flags)
        ^^^^^^^^^^^^^^^^^^^^^^^^^^^^^^^^^^^^^^^^^^^^^^^^^^^^^^^^^^^
  File "C:\Program Files\Python313\Lib\concurrent\futures\thread.py", line 59, in run
    result = self.fn(*self.args, **self.kwargs)
  File "C:\Program Files\Python313\Lib\socket.py", line 975, in getaddrinfo
    for res in _socket.getaddrinfo(host, port, family, type, proto, flags):
               ~~~~~~~~~~~~~~~~~~~^^^^^^^^^^^^^^^^^^^^^^^^^^^^^^^^^^^^^^^^
socket.gaierror: [Errno 11001] getaddrinfo failed

The above exception was the direct cause of the following exception:

Traceback (most recent call last):
  File "C:\Users\techd\AppData\Roaming\Python\Python313\site-packages\discord\client.py", line 664, in connect
    self.ws = await asyncio.wait_for(coro, timeout=60.0)
              ^^^^^^^^^^^^^^^^^^^^^^^^^^^^^^^^^^^^^^^^^^
  File "C:\Program Files\Python313\Lib\asyncio\tasks.py", line 507, in wait_for
    return await fut
           ^^^^^^^^^
  File "C:\Users\techd\AppData\Roaming\Python\Python313\site-packages\discord\gateway.py", line 374, in from_client
    socket = await client.http.ws_connect(str(url))
             ^^^^^^^^^^^^^^^^^^^^^^^^^^^^^^^^^^^^^^
  File "C:\Users\techd\AppData\Roaming\Python\Python313\site-packages\discord\http.py", line 550, in ws_connect
    return await self.__session.ws_connect(url, **kwargs)
           ^^^^^^^^^^^^^^^^^^^^^^^^^^^^^^^^^^^^^^^^^^^^^^
  File "C:\Users\techd\AppData\Roaming\Python\Python313\site-packages\aiohttp\client.py", line 1004, in _ws_connect
    resp = await self.request(
           ^^^^^^^^^^^^^^^^^^^
    ...<11 lines>...
    )
    ^
  File "C:\Users\techd\AppData\Roaming\Python\Python313\site-packages\aiohttp\client.py", line 703, in _request
    conn = await self._connector.connect(
           ^^^^^^^^^^^^^^^^^^^^^^^^^^^^^^
        req, traces=traces, timeout=real_timeout
        ^^^^^^^^^^^^^^^^^^^^^^^^^^^^^^^^^^^^^^^^
    )
    ^
  File "C:\Users\techd\AppData\Roaming\Python\Python313\site-packages\aiohttp\connector.py", line 548, in connect
    proto = await self._create_connection(req, traces, timeout)
            ^^^^^^^^^^^^^^^^^^^^^^^^^^^^^^^^^^^^^^^^^^^^^^^^^^^
  File "C:\Users\techd\AppData\Roaming\Python\Python313\site-packages\aiohttp\connector.py", line 1056, in _create_connection
    _, proto = await self._create_direct_connection(req, traces, timeout)
               ^^^^^^^^^^^^^^^^^^^^^^^^^^^^^^^^^^^^^^^^^^^^^^^^^^^^^^^^^^
  File "C:\Users\techd\AppData\Roaming\Python\Python313\site-packages\aiohttp\connector.py", line 1357, in _create_direct_connection
    raise ClientConnectorDNSError(req.connection_key, exc) from exc
aiohttp.client_exceptions.ClientConnectorDNSError: Cannot connect to host gateway-us-east1-d.discord.gg:443 ssl:default [getaddrinfo failed]
2025-02-05 14:31:30,639 - discord.gateway - INFO - Shard ID None has successfully RESUMED session 95dcb6d21c2e18b9e2229f95523d370a.
2025-02-05 14:46:32,814 - bot.connection - INFO - Web server shutdown complete
2025-02-05 14:46:35,862 - discord.client - INFO - logging in using static token
2025-02-05 14:46:37,818 - bot.connection - INFO - Starting web server on 0.0.0.0:8080
2025-02-05 14:46:37,819 - bot.connection - INFO - Web server running at http://0.0.0.0:8080
2025-02-05 14:46:37,956 - bot.commands - INFO - Cleared commands from guild 947925127654412370
2025-02-05 14:46:38,344 - bot.commands - INFO - Synced commands globally
2025-02-05 14:46:38,812 - discord.gateway - INFO - Shard ID None has connected to Gateway (Session ID: 8ec143ac9c50cd323d16074969d1670b).
2025-02-05 14:47:19,956 - bot.connection - INFO - Web server shutdown complete
2025-02-07 00:18:31,138 - discord.client - INFO - logging in using static token
2025-02-07 00:18:31,844 - bot.connection - INFO - Starting web server on 0.0.0.0:8080
2025-02-07 00:18:31,845 - bot.connection - INFO - Web server running at http://0.0.0.0:8080
2025-02-07 00:18:31,977 - bot.commands - INFO - Cleared commands from guild 947925127654412370
2025-02-07 00:18:32,210 - bot.commands - INFO - Synced commands globally
2025-02-07 00:18:33,133 - discord.gateway - INFO - Shard ID None has connected to Gateway (Session ID: 003aba029b22675105880497916f93d5).
2025-02-07 00:18:35,643 - bot.heartbeat - WARNING - Heartbeat failed with status 530
2025-02-07 00:19:07,613 - discord.ext.commands.bot - ERROR - Ignoring exception in command analyze
Traceback (most recent call last):
  File "C:\Users\techd\AppData\Roaming\Python\Python313\site-packages\discord\ext\commands\bot.py", line 1366, in invoke
    await ctx.command.invoke(ctx)
  File "C:\Users\techd\AppData\Roaming\Python\Python313\site-packages\discord\ext\commands\core.py", line 1021, in invoke
    await self.prepare(ctx)
  File "C:\Users\techd\AppData\Roaming\Python\Python313\site-packages\discord\ext\commands\core.py", line 938, in prepare
    await self._parse_arguments(ctx)
  File "C:\Users\techd\AppData\Roaming\Python\Python313\site-packages\discord\ext\commands\hybrid.py", line 537, in _parse_arguments
    return await super()._parse_arguments(ctx)
           ^^^^^^^^^^^^^^^^^^^^^^^^^^^^^^^^^^^
  File "C:\Users\techd\AppData\Roaming\Python\Python313\site-packages\discord\ext\commands\core.py", line 853, in _parse_arguments
    kwargs[name] = await self.transform(ctx, param, attachments)
                   ^^^^^^^^^^^^^^^^^^^^^^^^^^^^^^^^^^^^^^^^^^^^^
  File "C:\Users\techd\AppData\Roaming\Python\Python313\site-packages\discord\ext\commands\core.py", line 697, in transform
    raise MissingRequiredArgument(param)
discord.ext.commands.errors.MissingRequiredArgument: text is a required argument that is missing.
2025-02-07 00:19:07,949 - discord.ext.commands.bot - ERROR - Ignoring exception in command analyze
Traceback (most recent call last):
  File "C:\Users\techd\AppData\Roaming\Python\Python313\site-packages\discord\ext\commands\bot.py", line 1366, in invoke
    await ctx.command.invoke(ctx)
  File "C:\Users\techd\AppData\Roaming\Python\Python313\site-packages\discord\ext\commands\core.py", line 1021, in invoke
    await self.prepare(ctx)
  File "C:\Users\techd\AppData\Roaming\Python\Python313\site-packages\discord\ext\commands\core.py", line 938, in prepare
    await self._parse_arguments(ctx)
  File "C:\Users\techd\AppData\Roaming\Python\Python313\site-packages\discord\ext\commands\hybrid.py", line 537, in _parse_arguments
    return await super()._parse_arguments(ctx)
           ^^^^^^^^^^^^^^^^^^^^^^^^^^^^^^^^^^^
  File "C:\Users\techd\AppData\Roaming\Python\Python313\site-packages\discord\ext\commands\core.py", line 853, in _parse_arguments
    kwargs[name] = await self.transform(ctx, param, attachments)
                   ^^^^^^^^^^^^^^^^^^^^^^^^^^^^^^^^^^^^^^^^^^^^^
  File "C:\Users\techd\AppData\Roaming\Python\Python313\site-packages\discord\ext\commands\core.py", line 697, in transform
    raise MissingRequiredArgument(param)
discord.ext.commands.errors.MissingRequiredArgument: text is a required argument that is missing.
2025-02-07 00:19:56,177 - bot.heartbeat - WARNING - Heartbeat failed with status 530
2025-02-07 00:21:39,418 - bot.connection - INFO - Web server shutdown complete
2025-02-07 00:21:43,939 - discord.client - INFO - logging in using static token
2025-02-07 00:21:44,606 - bot.connection - INFO - Starting web server on 0.0.0.0:8080
2025-02-07 00:21:44,608 - bot.connection - INFO - Web server running at http://0.0.0.0:8080
2025-02-07 00:21:44,745 - bot.commands - INFO - Cleared commands from guild 947925127654412370
2025-02-07 00:21:44,976 - bot.commands - INFO - Synced commands globally
2025-02-07 00:21:45,909 - discord.gateway - INFO - Shard ID None has connected to Gateway (Session ID: 8009a7fae831d92e4fd4e29161c2043b).
2025-02-07 00:21:48,568 - bot.heartbeat - WARNING - Heartbeat failed with status 530
2025-02-07 00:23:10,047 - bot.heartbeat - WARNING - Heartbeat failed with status 530
2025-02-07 00:26:32,464 - bot.heartbeat - WARNING - Heartbeat failed with status 530
2025-02-07 00:31:40,550 - bot.heartbeat - WARNING - Heartbeat failed with status 530
2025-02-07 00:34:33,101 - bot.connection - INFO - Web server shutdown complete
2025-02-07 00:34:37,658 - discord.client - INFO - logging in using static token
2025-02-07 00:34:38,495 - bot.connection - INFO - Starting web server on 0.0.0.0:8080
2025-02-07 00:34:38,495 - bot.connection - INFO - Web server running at http://0.0.0.0:8080
2025-02-07 00:34:38,621 - bot.commands - INFO - Cleared commands from guild 947925127654412370
2025-02-07 00:34:38,968 - bot.commands - INFO - Synced commands globally
2025-02-07 00:34:39,343 - discord.gateway - INFO - Shard ID None has connected to Gateway (Session ID: ab61a71e61e6712b3216f3cff5c17e3a).
2025-02-07 00:34:41,550 - bot.heartbeat - WARNING - Heartbeat failed with status 530
2025-02-07 00:36:09,425 - discord.ext.commands.bot - ERROR - Ignoring exception in command analyze
Traceback (most recent call last):
  File "C:\Users\techd\AppData\Roaming\Python\Python313\site-packages\discord\ext\commands\bot.py", line 1366, in invoke
    await ctx.command.invoke(ctx)
  File "C:\Users\techd\AppData\Roaming\Python\Python313\site-packages\discord\ext\commands\core.py", line 1021, in invoke
    await self.prepare(ctx)
  File "C:\Users\techd\AppData\Roaming\Python\Python313\site-packages\discord\ext\commands\core.py", line 938, in prepare
    await self._parse_arguments(ctx)
  File "C:\Users\techd\AppData\Roaming\Python\Python313\site-packages\discord\ext\commands\hybrid.py", line 537, in _parse_arguments
    return await super()._parse_arguments(ctx)
           ^^^^^^^^^^^^^^^^^^^^^^^^^^^^^^^^^^^
  File "C:\Users\techd\AppData\Roaming\Python\Python313\site-packages\discord\ext\commands\core.py", line 853, in _parse_arguments
    kwargs[name] = await self.transform(ctx, param, attachments)
                   ^^^^^^^^^^^^^^^^^^^^^^^^^^^^^^^^^^^^^^^^^^^^^
  File "C:\Users\techd\AppData\Roaming\Python\Python313\site-packages\discord\ext\commands\core.py", line 697, in transform
    raise MissingRequiredArgument(param)
discord.ext.commands.errors.MissingRequiredArgument: text is a required argument that is missing.
2025-02-07 00:36:09,927 - discord.ext.commands.bot - ERROR - Ignoring exception in command analyze
Traceback (most recent call last):
  File "C:\Users\techd\AppData\Roaming\Python\Python313\site-packages\discord\ext\commands\bot.py", line 1366, in invoke
    await ctx.command.invoke(ctx)
  File "C:\Users\techd\AppData\Roaming\Python\Python313\site-packages\discord\ext\commands\core.py", line 1021, in invoke
    await self.prepare(ctx)
  File "C:\Users\techd\AppData\Roaming\Python\Python313\site-packages\discord\ext\commands\core.py", line 938, in prepare
    await self._parse_arguments(ctx)
  File "C:\Users\techd\AppData\Roaming\Python\Python313\site-packages\discord\ext\commands\hybrid.py", line 537, in _parse_arguments
    return await super()._parse_arguments(ctx)
           ^^^^^^^^^^^^^^^^^^^^^^^^^^^^^^^^^^^
  File "C:\Users\techd\AppData\Roaming\Python\Python313\site-packages\discord\ext\commands\core.py", line 853, in _parse_arguments
    kwargs[name] = await self.transform(ctx, param, attachments)
                   ^^^^^^^^^^^^^^^^^^^^^^^^^^^^^^^^^^^^^^^^^^^^^
  File "C:\Users\techd\AppData\Roaming\Python\Python313\site-packages\discord\ext\commands\core.py", line 697, in transform
    raise MissingRequiredArgument(param)
discord.ext.commands.errors.MissingRequiredArgument: text is a required argument that is missing.
2025-02-07 00:36:11,101 - bot.heartbeat - WARNING - Heartbeat failed with status 530
2025-02-07 00:37:25,337 - discord.ext.commands.bot - ERROR - Ignoring exception in command mood
Traceback (most recent call last):
  File "C:\Users\techd\AppData\Roaming\Python\Python313\site-packages\discord\ext\commands\core.py", line 235, in wrapped
    ret = await coro(*args, **kwargs)
          ^^^^^^^^^^^^^^^^^^^^^^^^^^^
  File "g:\Shared\Project Maplebot\bot\main.py", line 823, in wrapper
    return await func(*args, **kwargs)
           ^^^^^^^^^^^^^^^^^^^^^^^^^^^
  File "g:\Shared\Project Maplebot\bot\main.py", line 1386, in mood
    settings = bot.guild_settings.get_settings(interaction.guild_id)
                                               ^^^^^^^^^^^^^^^^^^^^
AttributeError: 'Context' object has no attribute 'guild_id'

The above exception was the direct cause of the following exception:

Traceback (most recent call last):
  File "C:\Users\techd\AppData\Roaming\Python\Python313\site-packages\discord\ext\commands\bot.py", line 1366, in invoke
    await ctx.command.invoke(ctx)
  File "C:\Users\techd\AppData\Roaming\Python\Python313\site-packages\discord\ext\commands\core.py", line 1029, in invoke
    await injected(*ctx.args, **ctx.kwargs)  # type: ignore
    ^^^^^^^^^^^^^^^^^^^^^^^^^^^^^^^^^^^^^^^
  File "C:\Users\techd\AppData\Roaming\Python\Python313\site-packages\discord\ext\commands\core.py", line 244, in wrapped
    raise CommandInvokeError(exc) from exc
discord.ext.commands.errors.CommandInvokeError: Command raised an exception: AttributeError: 'Context' object has no attribute 'guild_id'
2025-02-07 00:37:25,950 - discord.ext.commands.bot - ERROR - Ignoring exception in command mood
Traceback (most recent call last):
  File "C:\Users\techd\AppData\Roaming\Python\Python313\site-packages\discord\ext\commands\core.py", line 235, in wrapped
    ret = await coro(*args, **kwargs)
          ^^^^^^^^^^^^^^^^^^^^^^^^^^^
  File "g:\Shared\Project Maplebot\bot\main.py", line 823, in wrapper
    return await func(*args, **kwargs)
           ^^^^^^^^^^^^^^^^^^^^^^^^^^^
  File "g:\Shared\Project Maplebot\bot\main.py", line 1386, in mood
    settings = bot.guild_settings.get_settings(interaction.guild_id)
                                               ^^^^^^^^^^^^^^^^^^^^
AttributeError: 'Context' object has no attribute 'guild_id'

The above exception was the direct cause of the following exception:

Traceback (most recent call last):
  File "C:\Users\techd\AppData\Roaming\Python\Python313\site-packages\discord\ext\commands\bot.py", line 1366, in invoke
    await ctx.command.invoke(ctx)
  File "C:\Users\techd\AppData\Roaming\Python\Python313\site-packages\discord\ext\commands\core.py", line 1029, in invoke
    await injected(*ctx.args, **ctx.kwargs)  # type: ignore
    ^^^^^^^^^^^^^^^^^^^^^^^^^^^^^^^^^^^^^^^
  File "C:\Users\techd\AppData\Roaming\Python\Python313\site-packages\discord\ext\commands\core.py", line 244, in wrapped
    raise CommandInvokeError(exc) from exc
discord.ext.commands.errors.CommandInvokeError: Command raised an exception: AttributeError: 'Context' object has no attribute 'guild_id'
2025-02-07 00:37:32,893 - discord.ext.commands.bot - ERROR - Ignoring exception in command mood
Traceback (most recent call last):
  File "C:\Users\techd\AppData\Roaming\Python\Python313\site-packages\discord\app_commands\commands.py", line 858, in _do_call
    return await self._callback(interaction, **params)  # type: ignore
           ^^^^^^^^^^^^^^^^^^^^^^^^^^^^^^^^^^^^^^^^^^^
  File "g:\Shared\Project Maplebot\bot\main.py", line 823, in wrapper
    return await func(*args, **kwargs)
           ^^^^^^^^^^^^^^^^^^^^^^^^^^^
  File "g:\Shared\Project Maplebot\bot\main.py", line 1386, in mood
    settings = bot.guild_settings.get_settings(interaction.guild_id)
                                               ^^^^^^^^^^^^^^^^^^^^
AttributeError: 'Context' object has no attribute 'guild_id'

The above exception was the direct cause of the following exception:

Traceback (most recent call last):
  File "C:\Users\techd\AppData\Roaming\Python\Python313\site-packages\discord\ext\commands\hybrid.py", line 444, in _invoke_with_namespace
    value = await self._do_call(ctx, ctx.kwargs)  # type: ignore
            ^^^^^^^^^^^^^^^^^^^^^^^^^^^^^^^^^^^^
  File "C:\Users\techd\AppData\Roaming\Python\Python313\site-packages\discord\app_commands\commands.py", line 876, in _do_call
    raise CommandInvokeError(self, e) from e
discord.app_commands.errors.CommandInvokeError: Command 'mood' raised an exception: AttributeError: 'Context' object has no attribute 'guild_id'

The above exception was the direct cause of the following exception:

Traceback (most recent call last):
  File "C:\Users\techd\AppData\Roaming\Python\Python313\site-packages\discord\ext\commands\hybrid.py", line 444, in _invoke_with_namespace
    value = await self._do_call(ctx, ctx.kwargs)  # type: ignore
            ^^^^^^^^^^^^^^^^^^^^^^^^^^^^^^^^^^^^
  File "C:\Users\techd\AppData\Roaming\Python\Python313\site-packages\discord\app_commands\commands.py", line 876, in _do_call
    raise CommandInvokeError(self, e) from e
discord.ext.commands.errors.HybridCommandError: Hybrid command raised an error: Command 'mood' raised an exception: AttributeError: 'Context' object has no attribute 'guild_id'
2025-02-07 00:39:33,052 - bot.heartbeat - WARNING - Heartbeat failed with status 530
2025-02-07 00:41:40,013 - bot.connection - INFO - Web server shutdown complete
2025-02-07 00:41:44,345 - discord.client - INFO - logging in using static token
2025-02-07 00:41:44,885 - bot.connection - INFO - Starting web server on 0.0.0.0:8080
2025-02-07 00:41:44,886 - bot.connection - INFO - Web server running at http://0.0.0.0:8080
2025-02-07 00:41:45,070 - bot.commands - INFO - Cleared commands from guild 947925127654412370
2025-02-07 00:41:45,277 - bot.commands - INFO - Synced commands globally
2025-02-07 00:41:45,755 - discord.gateway - INFO - Shard ID None has connected to Gateway (Session ID: 10972c035b629816b99a7fa7ad3233ca).
2025-02-07 00:41:47,940 - bot.heartbeat - WARNING - Heartbeat failed with status 530
2025-02-07 00:41:51,151 - discord.ext.commands.bot - ERROR - Ignoring exception in command analyze
Traceback (most recent call last):
  File "C:\Users\techd\AppData\Roaming\Python\Python313\site-packages\discord\ext\commands\bot.py", line 1366, in invoke
    await ctx.command.invoke(ctx)
  File "C:\Users\techd\AppData\Roaming\Python\Python313\site-packages\discord\ext\commands\core.py", line 1021, in invoke
    await self.prepare(ctx)
  File "C:\Users\techd\AppData\Roaming\Python\Python313\site-packages\discord\ext\commands\core.py", line 938, in prepare
    await self._parse_arguments(ctx)
  File "C:\Users\techd\AppData\Roaming\Python\Python313\site-packages\discord\ext\commands\hybrid.py", line 537, in _parse_arguments
    return await super()._parse_arguments(ctx)
           ^^^^^^^^^^^^^^^^^^^^^^^^^^^^^^^^^^^
  File "C:\Users\techd\AppData\Roaming\Python\Python313\site-packages\discord\ext\commands\core.py", line 853, in _parse_arguments
    kwargs[name] = await self.transform(ctx, param, attachments)
                   ^^^^^^^^^^^^^^^^^^^^^^^^^^^^^^^^^^^^^^^^^^^^^
  File "C:\Users\techd\AppData\Roaming\Python\Python313\site-packages\discord\ext\commands\core.py", line 697, in transform
    raise MissingRequiredArgument(param)
discord.ext.commands.errors.MissingRequiredArgument: text is a required argument that is missing.
2025-02-07 00:41:51,683 - discord.ext.commands.bot - ERROR - Ignoring exception in command analyze
Traceback (most recent call last):
  File "C:\Users\techd\AppData\Roaming\Python\Python313\site-packages\discord\ext\commands\bot.py", line 1366, in invoke
    await ctx.command.invoke(ctx)
  File "C:\Users\techd\AppData\Roaming\Python\Python313\site-packages\discord\ext\commands\core.py", line 1021, in invoke
    await self.prepare(ctx)
  File "C:\Users\techd\AppData\Roaming\Python\Python313\site-packages\discord\ext\commands\core.py", line 938, in prepare
    await self._parse_arguments(ctx)
  File "C:\Users\techd\AppData\Roaming\Python\Python313\site-packages\discord\ext\commands\hybrid.py", line 537, in _parse_arguments
    return await super()._parse_arguments(ctx)
           ^^^^^^^^^^^^^^^^^^^^^^^^^^^^^^^^^^^
  File "C:\Users\techd\AppData\Roaming\Python\Python313\site-packages\discord\ext\commands\core.py", line 853, in _parse_arguments
    kwargs[name] = await self.transform(ctx, param, attachments)
                   ^^^^^^^^^^^^^^^^^^^^^^^^^^^^^^^^^^^^^^^^^^^^^
  File "C:\Users\techd\AppData\Roaming\Python\Python313\site-packages\discord\ext\commands\core.py", line 697, in transform
    raise MissingRequiredArgument(param)
discord.ext.commands.errors.MissingRequiredArgument: text is a required argument that is missing.
2025-02-07 00:43:17,677 - bot.heartbeat - WARNING - Heartbeat failed with status 530
2025-02-07 00:47:06,887 - bot.heartbeat - WARNING - Heartbeat failed with status 530
2025-02-07 00:49:09,799 - bot.connection - INFO - Web server shutdown complete
2025-02-07 00:52:18,186 - discord.client - INFO - logging in using static token
2025-02-07 00:52:18,951 - bot.connection - INFO - Starting web server on 0.0.0.0:8080
2025-02-07 00:52:18,952 - bot.connection - INFO - Web server running at http://0.0.0.0:8080
2025-02-07 00:52:19,075 - bot.commands - INFO - Cleared commands from guild 947925127654412370
2025-02-07 00:52:19,459 - bot.commands - INFO - Synced commands globally
2025-02-07 00:52:19,957 - discord.gateway - INFO - Shard ID None has connected to Gateway (Session ID: 23794702b8197c8b80ba9c04117a1e5a).
2025-02-07 00:52:22,228 - bot.heartbeat - WARNING - Heartbeat failed with status 530
2025-02-07 00:54:11,979 - bot.heartbeat - WARNING - Heartbeat failed with status 530
2025-02-07 00:57:15,323 - bot.heartbeat - WARNING - Heartbeat failed with status 530
2025-02-07 01:00:36,780 - bot.connection - INFO - Web server shutdown complete
2025-02-07 01:00:39,735 - discord.client - INFO - logging in using static token
2025-02-07 01:00:40,883 - bot.connection - INFO - Starting web server on 0.0.0.0:8080
2025-02-07 01:00:40,884 - bot.connection - INFO - Web server running at http://0.0.0.0:8080
2025-02-07 01:00:41,013 - bot.commands - INFO - Cleared commands from guild 947925127654412370
2025-02-07 01:00:41,387 - bot.commands - INFO - Synced commands globally
2025-02-07 01:00:41,854 - discord.gateway - INFO - Shard ID None has connected to Gateway (Session ID: c18a3494c3d0a10fe5da222efbf7b8bf).
2025-02-07 01:00:44,128 - bot.heartbeat - WARNING - Heartbeat failed with status 530
2025-02-07 01:02:11,917 - discord.ext.commands.bot - ERROR - Ignoring exception in command setpuppy
Traceback (most recent call last):
  File "C:\Users\techd\AppData\Roaming\Python\Python313\site-packages\discord\ext\commands\bot.py", line 1366, in invoke
    await ctx.command.invoke(ctx)
  File "C:\Users\techd\AppData\Roaming\Python\Python313\site-packages\discord\ext\commands\core.py", line 1021, in invoke
    await self.prepare(ctx)
  File "C:\Users\techd\AppData\Roaming\Python\Python313\site-packages\discord\ext\commands\core.py", line 938, in prepare
    await self._parse_arguments(ctx)
  File "C:\Users\techd\AppData\Roaming\Python\Python313\site-packages\discord\ext\commands\hybrid.py", line 537, in _parse_arguments
    return await super()._parse_arguments(ctx)
           ^^^^^^^^^^^^^^^^^^^^^^^^^^^^^^^^^^^
  File "C:\Users\techd\AppData\Roaming\Python\Python313\site-packages\discord\ext\commands\core.py", line 845, in _parse_arguments
    transformed = await self.transform(ctx, param, attachments)
                  ^^^^^^^^^^^^^^^^^^^^^^^^^^^^^^^^^^^^^^^^^^^^^
  File "C:\Users\techd\AppData\Roaming\Python\Python313\site-packages\discord\ext\commands\core.py", line 697, in transform
    raise MissingRequiredArgument(param)
discord.ext.commands.errors.MissingRequiredArgument: setting is a required argument that is missing.
2025-02-07 01:02:11,920 - discord.ext.commands.bot - ERROR - Ignoring exception in command setpuppy
Traceback (most recent call last):
  File "C:\Users\techd\AppData\Roaming\Python\Python313\site-packages\discord\ext\commands\bot.py", line 1366, in invoke
    await ctx.command.invoke(ctx)
  File "C:\Users\techd\AppData\Roaming\Python\Python313\site-packages\discord\ext\commands\core.py", line 1021, in invoke
    await self.prepare(ctx)
  File "C:\Users\techd\AppData\Roaming\Python\Python313\site-packages\discord\ext\commands\core.py", line 938, in prepare
    await self._parse_arguments(ctx)
  File "C:\Users\techd\AppData\Roaming\Python\Python313\site-packages\discord\ext\commands\hybrid.py", line 537, in _parse_arguments
    return await super()._parse_arguments(ctx)
           ^^^^^^^^^^^^^^^^^^^^^^^^^^^^^^^^^^^
  File "C:\Users\techd\AppData\Roaming\Python\Python313\site-packages\discord\ext\commands\core.py", line 845, in _parse_arguments
    transformed = await self.transform(ctx, param, attachments)
                  ^^^^^^^^^^^^^^^^^^^^^^^^^^^^^^^^^^^^^^^^^^^^^
  File "C:\Users\techd\AppData\Roaming\Python\Python313\site-packages\discord\ext\commands\core.py", line 697, in transform
    raise MissingRequiredArgument(param)
discord.ext.commands.errors.MissingRequiredArgument: setting is a required argument that is missing.
2025-02-07 01:02:40,892 - bot.heartbeat - WARNING - Heartbeat failed with status 530
2025-02-07 01:03:00,455 - discord.ext.commands.bot - ERROR - Ignoring exception in command None
discord.ext.commands.errors.CommandNotFound: Command "listpuppy" is not found
2025-02-07 01:03:00,456 - discord.ext.commands.bot - ERROR - Ignoring exception in command None
discord.ext.commands.errors.CommandNotFound: Command "listpuppy" is not found
2025-02-07 01:04:53,805 - discord.ext.commands.bot - ERROR - Ignoring exception in command None
discord.ext.commands.errors.CommandNotFound: Command "listpuppy" is not found
2025-02-07 01:04:53,806 - discord.ext.commands.bot - ERROR - Ignoring exception in command None
discord.ext.commands.errors.CommandNotFound: Command "listpuppy" is not found
2025-02-07 01:06:29,471 - bot.heartbeat - WARNING - Heartbeat failed with status 530
2025-02-07 01:09:44,116 - bot.connection - INFO - Web server shutdown complete
2025-02-07 01:09:47,472 - discord.client - INFO - logging in using static token
2025-02-07 01:09:48,112 - bot.connection - INFO - Starting web server on 0.0.0.0:8080
2025-02-07 01:09:48,113 - bot.connection - INFO - Web server running at http://0.0.0.0:8080
2025-02-07 01:09:48,262 - bot.commands - INFO - Cleared commands from guild 947925127654412370
2025-02-07 01:09:48,487 - bot.commands - INFO - Synced commands globally
2025-02-07 01:09:49,069 - discord.gateway - INFO - Shard ID None has connected to Gateway (Session ID: 6fdbda3ed10992e00db796e331fae884).
2025-02-07 01:09:51,255 - bot.heartbeat - WARNING - Heartbeat failed with status 530
2025-02-07 01:11:45,238 - bot.heartbeat - WARNING - Heartbeat failed with status 530
2025-02-07 01:14:15,361 - bot.connection - INFO - Web server shutdown complete
2025-02-07 01:14:18,842 - discord.client - INFO - logging in using static token
2025-02-07 01:14:19,491 - bot.connection - INFO - Starting web server on 0.0.0.0:8080
2025-02-07 01:14:19,492 - bot.connection - INFO - Web server running at http://0.0.0.0:8080
2025-02-07 01:14:19,632 - bot.commands - INFO - Cleared commands from guild 947925127654412370
2025-02-07 01:14:19,850 - bot.commands - INFO - Synced commands globally
2025-02-07 01:14:20,234 - discord.gateway - INFO - Shard ID None has connected to Gateway (Session ID: 66d1303554def20bb9cf37f396a61631).
2025-02-07 01:14:22,425 - bot.heartbeat - WARNING - Heartbeat failed with status 530
2025-02-07 01:15:49,871 - bot.connection - INFO - Web server shutdown complete
2025-02-07 01:15:52,815 - discord.client - INFO - logging in using static token
2025-02-07 01:15:53,332 - bot.connection - INFO - Starting web server on 0.0.0.0:8080
2025-02-07 01:15:53,333 - bot.connection - INFO - Web server running at http://0.0.0.0:8080
2025-02-07 01:15:53,510 - bot.commands - INFO - Cleared commands from guild 947925127654412370
2025-02-07 01:15:53,752 - bot.commands - INFO - Synced commands globally
2025-02-07 01:15:54,187 - discord.gateway - INFO - Shard ID None has connected to Gateway (Session ID: b8c1f74567785af1641e34e2315b4caa).
2025-02-07 01:15:56,725 - bot.heartbeat - WARNING - Heartbeat failed with status 530
2025-02-07 01:16:28,866 - bot.commands - INFO - Cleared commands from guild 947925127654412370
2025-02-07 01:16:34,706 - bot.connection - INFO - Web server shutdown complete
2025-02-07 01:16:37,543 - discord.client - INFO - logging in using static token
2025-02-07 01:16:38,077 - bot.connection - INFO - Starting web server on 0.0.0.0:8080
2025-02-07 01:16:38,078 - bot.connection - INFO - Web server running at http://0.0.0.0:8080
2025-02-07 01:16:57,486 - bot.connection - INFO - Web server shutdown complete
2025-02-07 01:17:00,410 - discord.client - INFO - logging in using static token
2025-02-07 01:17:01,009 - bot.connection - INFO - Starting web server on 0.0.0.0:8080
2025-02-07 01:17:01,010 - bot.connection - INFO - Web server running at http://0.0.0.0:8080
2025-02-07 01:17:58,890 - bot.commands - INFO - Cleared commands from guild 947925127654412370
2025-02-07 01:17:59,335 - bot.commands - INFO - Synced commands globally
2025-02-07 01:17:59,675 - discord.gateway - INFO - Shard ID None has connected to Gateway (Session ID: 005adeba4cade8f5e431a486b77080a4).
2025-02-07 01:18:02,362 - bot.heartbeat - WARNING - Heartbeat failed with status 530
2025-02-07 01:18:20,763 - discord.app_commands.tree - ERROR - Ignoring exception in command tree
Traceback (most recent call last):
  File "C:\Users\techd\AppData\Roaming\Python\Python313\site-packages\discord\app_commands\tree.py", line 1151, in wrapper
    await self._call(interaction)
  File "C:\Users\techd\AppData\Roaming\Python\Python313\site-packages\discord\app_commands\tree.py", line 1283, in _call
    command, options = self._get_app_command_options(data)
                       ~~~~~~~~~~~~~~~~~~~~~~~~~~~~~^^^^^^
  File "C:\Users\techd\AppData\Roaming\Python\Python313\site-packages\discord\app_commands\tree.py", line 1187, in _get_app_command_options
    raise CommandNotFound(name, parents)
discord.app_commands.errors.CommandNotFound: Application command 'checkcommands' not found
2025-02-07 01:18:59,745 - bot.commands - INFO - Cleared global commands
2025-02-07 01:19:01,268 - bot.commands - INFO - Synced commands to dev guild 947925127654412370
2025-02-07 01:19:36,975 - bot.heartbeat - WARNING - Heartbeat failed with status 530
2025-02-07 01:22:12,825 - bot.connection - INFO - Web server shutdown complete
2025-02-07 01:22:16,184 - discord.client - INFO - logging in using static token
2025-02-07 01:22:16,687 - bot.connection - INFO - Starting web server on 0.0.0.0:8080
2025-02-07 01:22:16,688 - bot.connection - INFO - Web server running at http://0.0.0.0:8080
2025-02-07 01:22:16,853 - bot.commands - INFO - Cleared commands from guild 947925127654412370
2025-02-07 01:22:17,184 - bot.commands - INFO - Synced commands globally
2025-02-07 01:22:18,094 - discord.gateway - INFO - Shard ID None has connected to Gateway (Session ID: 921fcfd0b960e4627e98c6829ca9ad10).
2025-02-07 01:22:20,281 - bot.heartbeat - WARNING - Heartbeat failed with status 530
2025-02-07 01:23:43,590 - bot.heartbeat - WARNING - Heartbeat failed with status 530
2025-02-07 01:24:19,155 - bot.connection - INFO - Web server shutdown complete
2025-02-07 01:24:22,231 - discord.client - INFO - logging in using static token
2025-02-07 01:24:22,738 - bot.connection - INFO - Starting web server on 0.0.0.0:8080
2025-02-07 01:24:22,739 - bot.connection - INFO - Web server running at http://0.0.0.0:8080
2025-02-07 01:24:22,864 - bot.commands - INFO - Cleared commands from guild 947925127654412370
2025-02-07 01:24:23,470 - bot.commands - INFO - Synced commands globally
2025-02-07 01:24:23,941 - discord.gateway - INFO - Shard ID None has connected to Gateway (Session ID: ece72823d705d709854db7b42b8c6743).
2025-02-07 01:24:26,141 - bot.heartbeat - WARNING - Heartbeat failed with status 530
2025-02-07 01:26:09,823 - bot.heartbeat - WARNING - Heartbeat failed with status 530
2025-02-07 01:27:29,707 - bot.connection - INFO - Web server shutdown complete
2025-02-07 01:27:32,850 - discord.client - INFO - logging in using static token
2025-02-07 01:27:33,421 - bot.connection - INFO - Starting web server on 0.0.0.0:8080
2025-02-07 01:27:33,422 - bot.connection - INFO - Web server running at http://0.0.0.0:8080
2025-02-07 01:27:33,630 - bot.commands - INFO - Cleared commands from guild 947925127654412370
2025-02-07 01:27:34,064 - bot.commands - INFO - Synced commands globally
2025-02-07 01:27:34,491 - discord.gateway - INFO - Shard ID None has connected to Gateway (Session ID: 935aae06d6bf45736b3bd98a2f79179d).
2025-02-07 01:27:36,682 - bot.heartbeat - WARNING - Heartbeat failed with status 530
2025-02-07 01:28:08,191 - bot.connection - INFO - Web server shutdown complete
